Workbook

Sheet Léeme
A1: Ancla del Alma · lista de materiales
A2: El Lago y el mar, amarrados a la cruz · hipótesis H = 200 cm, W = 150 cm
A5: Antes de comprar
A6: No se corta tela ni se imprime el pliego DTF hasta medir la réplica (24–27 oct). Las cantidades de tela, cordón y galón están calculadas para H = 200 cm y W = 150 cm: si la réplica mide distinto, las telas se multiplican por H/200 y los galones y cordones del contorno por el perímetro nuevo. Las piedras y perlas no cambian si el factor queda entre 0,95 y 1,05.
A8: Hojas
A9: Compras: todo lo que hay que comprar, con la cantidad de diseño, la reposición y lo que se compra. Aquí se anotan proveedor, precio y si ya se compró.
A10: Piedras por zona: cada piedra y perla del diseño por zona, talla y tono, y la comprobación contra Compras.
A11: Capas y peso: las 11 capas, sus materiales y el presupuesto de peso.
A12: Patrón: las 12 piezas de tela (P01–P12) con medidas y márgenes.
A13: Piezas DTF: las 18 piezas del pliego, cuántas van en el manto y cuántas de repuesto.
A14: Herramientas: lo que hace falta en el taller, para marcar si ya se tiene.
A16: Colores
... A26: taller/11-ancla-del-alma/piezas.json (materiales, patrón, capas, fases y pruebas) y datos/piedras.json (cada piedra con su posición). Este libro se rehace con herramientas/materiales.py.

Sheet Compras
A1: Compras
A2: Cantidades para H = 200 cm, W = 150 cm. Las piedras y perlas llevan la reposición de la celda C3.
A3: Reposición de piedras y perlas | C3: 0.15 | E3: Moneda | F3: USD
A5: Código | B5: Grupo | C5: Material | D5: Especificación | E5: Cantidad de diseño | F5: Unidad | G5: Reposición | H5: A comprar | I5: Uso | J5: Capas | K5: Pruebas (26–28 oct) | L5: Se usa desde | M5: Cuándo comprar | N5: Proveedor | O5: Precio unitario | P5: Subtotal | Q5: Comprado
A6: M01 | B6: Telas | C6: Terciopelo esmeralda profundo | D6: Rayón o viscosa (mejor caída) o poliéster de buena calidad; ≈ #0F6652; ancho 1,40–1,50 m | E6: 4.2 | F6: m | G6: 0 | H6: =E6*(1+G6) | I6: Cuerpo 2,1 m; vueltas, nesgas y retazos de muestra 2,1 m | J6: 4 Vueltas de los bordes, 6 Cuerpo de terciopelo | K6: 1, 3, 4, 8 | L6: 27 oct (F05) | M6: Primero tres muestras de 30 cm para la prueba 4; el largo completo, en cuanto se elija el tono. | P6: =IF(O6="","",H6*O6)
A7: M02 | B7: Telas | C7: Raso o tafetán esmeralda hondo | D7: Poliéster, ≈ #063A31 | E7: 2.3 | F7: m | G7: 0 | H7: =E7*(1+G7) | I7: Forro: entero con tela de 1,50 m; con 1,40 m, dos mitades encontradas en el mismo largo | J7: 3 Forro | K7: 2, 8 | L7: 11 nov (F17) | M7: Una muestra para la prueba 2 (control) y la 8. | P7: =IF(O7="","",H7*O7)
A8: M03 | B8: Telas | C8: Tafetán esmeralda hondo | D8: Poliéster | E8: 0.7 | F8: m | G8: 0 | H8: =E8*(1+G8) | I8: Protector de roce (pieza de 65 × 95 cm al través) | J8: 2 Protector de roce | L8: 11 nov (F17) | P8: =IF(O8="","",H8*O8)
A9: M04 | B9: DTF | C9: Raso duquesa marfil | D9: Poliéster, ≈ #F3EBDD | E9: 0.6 | F9: m | G9: 0 | H9: =E9*(1+G9) | I9: Base de las 36 piezas DTF (más repuestos) | J9: 8 Apliques: cruz y paneles DTF | K9: 2 | L9: 26 oct (F04) | P9: =IF(O9="","",H9*O9)
A10: M05 | B10: DTF | C10: Impresión DTF | D10: Pliego de 56 × 98 cm (película de 60 cm), PNG a 300 ppp, polvo antimigración, capa blanca al 50 % | E10: 2 | F10: pliegos | G10: 0 | H10: =E10*(1+G10) | I10: Uno de producción y una tira de prueba (prueba 2) | J10: 8 Apliques: cruz y paneles DTF | K10: 2 | L10: 26 oct (F04) | M10: La tira de prueba ya. El pliego de producción solo después de medir la réplica y aprobar la prueba 2. | P10: =IF(O10="","",H10*O10)
A11: M06 | B11: DTF | C11: Entretela termoadhesiva fina | D11: Tejida o no tejida, de baja temperatura | E11: 0.6 | F11: m | G11: 0 | H11: =E11*(1+G11) | I11: Estabiliza el raso antes de prensar | J11: 8 Apliques: cruz y paneles DTF | K11: 2 | L11: 26 oct (F04) | P11: =IF(O11="","",H11*O11)
A12: M07 | B12: DTF | C12: Fieltro fino marfil | D12: 1–2 mm | E12: 0.3 | F12: m² | G12: 0 | H12: =E12*(1+G12) | I12: Relleno de azucenas y crestas | J12: 8 Apliques: cruz y paneles DTF | K12: 2 | L12: 26 oct (F04) | P12: =IF(O12="","",H12*O12)
A13: M08 | B13: Soportes | C13: Organza de algodón o lino ligero | D13: Ancho 1,50 m | E13: 3 | F13: m | G13: 0 | H13: =E13*(1+G13) | I13: Bajo todo lo bordado; doble bajo el pavé | J13: 5 Organza de soporte y refuerzo del pie | K13: 1 | L13: 27 oct (F05) | P13: =IF(O13="","",H13*O13)
A14: M09 | B14: Soportes | C14: Cinta de algodón de 2 cm | D14: Tejida | E14: 1.6 | F14: m | G14: 0 | H14: =E14*(1+G14) | I14: Refuerzo del pie | J14: 5 Organza de soporte y refuerzo del pie | L14: 27 oct (F05) | P14: =IF(O14="","",H14*O14)
A15: M10 | B15: Soportes | C15: Lienzo de algodón | D15: Tejido firme | E15: 0.6 | F15: m | G15: 0 | H15: =E15*(1+G15) | I15: Soporte para bordar la cruz aparte | J15: 8 Apliques: cruz y paneles DTF | L15: 26 oct (F04) | P15: =IF(O15="","",H15*O15)
A16: M11 | B16: Soportes | C16: Cartulina o fieltro fino para realce | D16: Amarilla u ocre, para que no se transparente | E16: 0.12 | F16: m² | G16: 0 | H16: =E16*(1+G16) | I16: Tres capas del realce de la cruz | J16: 8 Apliques: cruz y paneles DTF | L16: 26 oct (F04) | P16: =IF(O16="","",H16*O16)
A17: M12 | B17: Soportes | C17: Papel de seda | D17: Pliegos grandes, para unir | E17: 6 | F17: m | G17: 0 | H17: =E17*(1+G17) | I17: Dibujo 1:1 del emblema, las azucenas, el horizonte y el degradado | L17: 21 oct (F01) | M17: Ya: hace falta para el dibujo 1:1. | P17: =IF(O17="","",H17*O17)
A18: M13 | B18: Hilos y cordones | C18: Cordón torcido de oro de 2 mm | D18: Metálico sintético | E18: 32 | F18: m | G18: 0 | H18: =E18*(1+G18) | I18: Perfil de la cruz y del ancla, amarra, tallos, hojas, olivo, horizonte, Basílica, Ávila y rayos finos | J18: 7 Bordado directo, 8 Apliques: cruz y paneles DTF, 9 Ancla y amarra | K18: 1 | L18: 26 oct (F04) | P18: =IF(O18="","",H18*O18)
A19: M14 | B19: Hilos y cordones | C19: Cordón de oro de 4 mm | D19: Metálico sintético | E19: 6.5 | F19: m | G19: 0 | H19: =E19*(1+G19) | I19: Contorno de los lados y el pie | J19: 11 Orla | L19: 10 nov (F15) | P19: =IF(O19="","",H19*O19)
A20: M15 | B20: Hilos y cordones | C20: Cordón de plata de 2 mm | D20: Metálico sintético | E20: 6 | F20: m | G20: 0 | H20: =E20*(1+G20) | I20: Perfil de las crestas | J20: 8 Apliques: cruz y paneles DTF | K20: 2 | L20: 26 oct (F04) | P20: =IF(O20="","",H20*O20)
A21: M16 | B21: Hilos y cordones | C21: Cordón marfil de 2 mm | D21: Satinado | E21: 4 | F21: m | G21: 0 | H21: =E21*(1+G21) | I21: Perfil de las azucenas y los capullos | J21: 8 Apliques: cruz y paneles DTF | K21: 2 | L21: 26 oct (F04) | P21: =IF(O21="","",H21*O21)
A22: M17 | B22: Hilos y cordones | C22: Cordón de oro viejo de 3 mm | D22: Metálico sintético, mate | E22: 1.5 | F22: m | G22: 0 | H22: =E22*(1+G22) | I22: Ribete del arranque | J22: 7 Bordado directo | L22: 30 oct (F07) | P22: =IF(O22="","",H22*O22)
A23: M18 | B23: Hilos y cordones | C23: Cordón champán de 2 mm | D23: Metálico sintético | E23: 1.5 | F23: m | G23: 0 | H23: =E23*(1+G23) | I23: Ribete del arranque | J23: 7 Bordado directo | L23: 30 oct (F07) | P23: =IF(O23="","",H23*O23)
A24: M19 | B24: Hilos y cordones | C24: Hilo para hilos tendidos e hilo plano tipo hojilla | D24: Oro viejo y oro, lámina sobre alma de poliéster | E24: 5 | F24: conos | G24: 0 | H24: =E24*(1+G24) | I24: Cruz, rayos, sol, camino de luz y Basílica | J24: 7 Bordado directo, 8 Apliques: cruz y paneles DTF | K24: 7 | L24: 26 oct (F04) | P24: =IF(O24="","",H24*O24)
A25: M20 | B25: Hilos y cordones | C25: Hilo metalizado azul Capri | D25: Para couching | E25: 2 | F25: conos | G25: 0 | H25: =E25*(1+G25) | I25: Líneas de las olas | J25: 7 Bordado directo | L25: 30 oct (F07) | P25: =IF(O25="","",H25*O25)
A26: M21 | B26: Hilos y cordones | C26: Hilo metalizado aguamarina | D26: Para couching | E26: 1 | F26: cono | G26: 0 | H26: =E26*(1+G26) | I26: Ondas del Lago | J26: 7 Bordado directo | L26: 30 oct (F07) | P26: =IF(O26="","",H26*O26)
A27: M22 | B27: Hilos y cordones | C27: Canutillo de oro liso y rizado | D27: Metálico | E27: 40 | F27: g | G27: 0 | H27: =E27*(1+G27) | I27: Cruz y estambres | J27: 8 Apliques: cruz y paneles DTF | L27: 26 oct (F04) | P27: =IF(O27="","",H27*O27)
A28: M23 | B28: Hilos y cordones | C28: Hilos de fijación y de pedrería | D28: Poliéster oro, marfil y verde; hilo encerado tipo Nymo | E28: 1 | F28: surtido | G28: 0 | H28: =E28*(1+G28) | I28: Fijar cordones, apliques, piedras y perlas | J28: 7 Bordado directo, 9 Ancla y amarra, 10 Degradado de pedrería | K28: 1, 3 | L28: 30 oct (F07) | P28: =IF(O28="","",H28*O28)
A29: S12 | B29: Piedras | C29: Rosa montada SS12 | D29: Champán 37, cristal 15 | E29: 52 | F29: u | G29: =$C$3 | H29: =ROUNDUP(E29*(1+G29),0) | I29: Tramos 4 y 5 | J29: 10 Degradado de pedrería | K29: 1, 3, 7 | L29: 6 nov (F13) | P29: =IF(O29="","",H29*O29)
A30: S16 | B30: Piedras | C30: Rosa montada SS16 | D30: Champán 295, aguamarina 40, cristal 35 | E30: 370 | F30: u | G30: =$C$3 | H30: =ROUNDUP(E30*(1+G30),0) | I30: Ancla y tramos 3 y 4 | J30: 9 Ancla y amarra, 10 Degradado de pedrería | K30: 1, 3, 7 | L30: 3 nov (F09) | P30: =IF(O30="","",H30*O30)
A31: S20 | B31: Piedras | C31: Rosa montada SS20 | D31: Aguamarina 130, cristal 90, champán 60, Capri 40 | E31: 320 | F31: u | G31: =$C$3 | H31: =ROUNDUP(E31*(1+G31),0) | I31: Uñas del ancla y tramos 2 y 3 | J31: 9 Ancla y amarra, 10 Degradado de pedrería | K31: 1, 3, 7 | L31: 3 nov (F09) | P31: =IF(O31="","",H31*O31)
A32: S30 | B32: Piedras | C32: Rosa montada SS30 | D32: Capri 150, aguamarina 110, cristal 80 | E32: 340 | F32: u | G32: =$C$3 | H32: =ROUNDUP(E32*(1+G32),0) | I32: Tramos 1 y 2 | J32: 10 Degradado de pedrería | K32: 1, 3, 7 | L32: 6 nov (F13) | P32: =IF(O32="","",H32*O32)
A33: S40 | B33: Piedras | C33: Rosa montada SS40 | D33: Capri 100, aguamarina 60 | E33: 160 | F33: u | G33: =$C$3 | H33: =ROUNDUP(E33*(1+G33),0) | I33: Pavé | J33: 10 Degradado de pedrería | K33: 1, 3, 7 | L33: 6 nov (F13) | P33: =IF(O33="","",H33*O33)
A34: C08 | B34: Piedras | C34: Chatón de 8 mm en garras | D34: Aguamarina 6, cristal 6, champán 2 | E34: 14 | F34: u | G34: =$C$3 | H34: =ROUNDUP(E34*(1+G34),0) | I34: Puntas de las uñas y tramo 2 | J34: 9 Ancla y amarra, 10 Degradado de pedrería | K34: 1, 3, 7 | L34: 3 nov (F09) | P34: =IF(O34="","",H34*O34)
A35: C10 | B35: Piedras | C35: Chatón de 10 mm en garras | D35: Capri 26, aguamarina 18, champán 1 | E35: 45 | F35: u | G35: =$C$3 | H35: =ROUNDUP(E35*(1+G35),0) | I35: Punta del ancla y pavé | J35: 9 Ancla y amarra, 10 Degradado de pedrería | K35: 1, 3, 7 | L35: 3 nov (F09) | P35: =IF(O35="","",H35*O35)
A36: O13 | B36: Piedras | C36: Óvalo facetado o cabujón de 13 × 18 mm en garras | D36: Capri 14, aguamarina 8 | E36: 22 | F36: u | G36: =$C$3 | H36: =ROUNDUP(E36*(1+G36),0) | I36: Pavé | J36: 10 Degradado de pedrería | K36: 1, 3, 7 | L36: 6 nov (F13) | P36: =IF(O36="","",H36*O36)
A37: P08 | B37: Perlas | C37: Perla de cristal crema de 8 mm | D37: Nacarada, con taladro | E37: 55 | F37: u | G37: =$C$3 | H37: =ROUNDUP(E37*(1+G37),0) | I37: Amarra 1, pavé 36, orla del pie 18 | J37: 9 Ancla y amarra, 10 Degradado de pedrería, 11 Orla | K37: 1, 3, 7 | L37: 3 nov (F09) | P37: =IF(O37="","",H37*O37)
A38: P06 | B38: Perlas | C38: Perla de cristal crema de 6 mm | D38: Nacarada, con taladro | E38: 198 | F38: u | G38: =$C$3 | H38: =ROUNDUP(E38*(1+G38),0) | I38: Amarra 10, olivo 12, tramo 2 40, pavé 110, orla de los lados 26 | J38: 9 Ancla y amarra, 10 Degradado de pedrería, 11 Orla | K38: 1, 3, 7 | L38: 3 nov (F09) | P38: =IF(O38="","",H38*O38)
A39: P04 | B39: Perlas | C39: Perla de cristal crema de 4 mm | D39: Nacarada, con taladro | E39: 262 | F39: u | G39: =$C$3 | H39: =ROUNDUP(E39*(1+G39),0) | I39: Ancla 130, tramo 5 12, tramo 4 20, tramo 3 30, tramo 2 70 | J39: 9 Ancla y amarra, 10 Degradado de pedrería | K39: 1, 3, 7 | L39: 3 nov (F09) | P39: =IF(O39="","",H39*O39)
A40: M28 | B40: Galones | C40: Galón de volutas barrocas doradas de 6–8 cm | D40: Si no hay volutas, encaje dorado que imite el oleaje | E40: 6 | F40: m | G40: 0 | H40: =E40*(1+G40) | I40: Orla de los lados y el pie | J40: 11 Orla | L40: 10 nov (F15) | P40: =IF(O40="","",H40*O40)
A41: M29 | B41: Galones | C41: Galón de oro de 1,5 cm | D41: Liso o de trencilla | E41: 5 | F41: m | G41: 0 | H41: =E41*(1+G41) | I41: Vueltas de los bordes | J41: 4 Vueltas de los bordes | K41: 8 | L41: 11 nov (F16) | P41: =IF(O41="","",H41*O41)
...

Sheet Piedras por zona
A1: Piedras y perlas por zona
A2: Una fila por zona, talla y tono, contadas sobre el plano de pedrería. A la derecha, los totales y la comprobación contra Compras.
A4: Zona | B4: Franja y (cm) | C4: Talla | D4: Código de compra | E4: Tono | F4: Cantidad | H4: Código | I4: Talla | J4: En el plano | K4: En Compras | L4: Diferencia
A5: Ancla | B5: 74–95 | C5: Rosa montada SS16 | D5: S16 | E5: Champán | F5: 250 | H5: S12 | I5: Rosa montada SS12 | J5: =SUMIFS($F$5:$F$48,$D$5:$D$48,H5) | K5: =INDEX(Compras!$E$6:$E$43,MATCH(H5,Compras!$A$6:$A$43,0)) | L5: =J5-K5
A6: Ancla | B6: 74–95 | C6: Rosa montada SS20 | D6: S20 | E6: Champán | F6: 60 | H6: S16 | I6: Rosa montada SS16 | J6: =SUMIFS($F$5:$F$48,$D$5:$D$48,H6) | K6: =INDEX(Compras!$E$6:$E$43,MATCH(H6,Compras!$A$6:$A$43,0)) | L6: =J6-K6
A7: Ancla | B7: 74–95 | C7: Chatón 8 mm | D7: C08 | E7: Champán | F7: 2 | H7: S20 | I7: Rosa montada SS20 | J7: =SUMIFS($F$5:$F$48,$D$5:$D$48,H7) | K7: =INDEX(Compras!$E$6:$E$43,MATCH(H7,Compras!$A$6:$A$43,0)) | L7: =J7-K7
A8: Ancla | B8: 74–95 | C8: Chatón 10 mm | D8: C10 | E8: Champán | F8: 1 | H8: S30 | I8: Rosa montada SS30 | J8: =SUMIFS($F$5:$F$48,$D$5:$D$48,H8) | K8: =INDEX(Compras!$E$6:$E$43,MATCH(H8,Compras!$A$6:$A$43,0)) | L8: =J8-K8
A9: Ancla | B9: 74–95 | C9: Perla 4 mm | D9: P04 | E9: Perla crema | F9: 130 | H9: S40 | I9: Rosa montada SS40 | J9: =SUMIFS($F$5:$F$48,$D$5:$D$48,H9) | K9: =INDEX(Compras!$E$6:$E$43,MATCH(H9,Compras!$A$6:$A$43,0)) | L9: =J9-K9
A10: Amarra | B10: 95–126,5 | C10: Perla 6 mm | D10: P06 | E10: Perla crema | F10: 10 | H10: C08 | I10: Chatón 8 mm | J10: =SUMIFS($F$5:$F$48,$D$5:$D$48,H10) | K10: =INDEX(Compras!$E$6:$E$43,MATCH(H10,Compras!$A$6:$A$43,0)) | L10: =J10-K10
A11: Amarra | B11: 95–126,5 | C11: Perla 8 mm | D11: P08 | E11: Perla crema | F11: 1 | H11: C10 | I11: Chatón 10 mm | J11: =SUMIFS($F$5:$F$48,$D$5:$D$48,H11) | K11: =INDEX(Compras!$E$6:$E$43,MATCH(H11,Compras!$A$6:$A$43,0)) | L11: =J11-K11
A12: Ramitos de olivo | B12: 109–121 | C12: Perla 6 mm | D12: P06 | E12: Perla crema | F12: 12 | H12: O13 | I12: Óvalo 13 × 18 mm | J12: =SUMIFS($F$5:$F$48,$D$5:$D$48,H12) | K12: =INDEX(Compras!$E$6:$E$43,MATCH(H12,Compras!$A$6:$A$43,0)) | L12: =J12-K12
A13: Tramo 5 | B13: 106–122 | C13: Rosa montada SS12 | D13: S12 | E13: Champán | F13: 12 | H13: P04 | I13: Perla 4 mm | J13: =SUMIFS($F$5:$F$48,$D$5:$D$48,H13) | K13: =INDEX(Compras!$E$6:$E$43,MATCH(H13,Compras!$A$6:$A$43,0)) | L13: =J13-K13
A14: Tramo 5 | B14: 106–122 | C14: Perla 4 mm | D14: P04 | E14: Perla crema | F14: 12 | H14: P06 | I14: Perla 6 mm | J14: =SUMIFS($F$5:$F$48,$D$5:$D$48,H14) | K14: =INDEX(Compras!$E$6:$E$43,MATCH(H14,Compras!$A$6:$A$43,0)) | L14: =J14-K14
A15: Tramo 4 | B15: 122–140 | C15: Rosa montada SS12 | D15: S12 | E15: Champán | F15: 25 | H15: P08 | I15: Perla 8 mm | J15: =SUMIFS($F$5:$F$48,$D$5:$D$48,H15) | K15: =INDEX(Compras!$E$6:$E$43,MATCH(H15,Compras!$A$6:$A$43,0)) | L15: =J15-K15
A16: Tramo 4 | B16: 122–140 | C16: Rosa montada SS12 | D16: S12 | E16: Cristal | F16: 15 | I16: Total | J16: =SUM(J5:J15) | K16: =SUM(K5:K15) | L16: =J16-K16
A17: Tramo 4 | B17: 122–140 | C17: Rosa montada SS16 | D17: S16 | E17: Champán | F17: 25
A18: Tramo 4 | B18: 122–140 | C18: Rosa montada SS16 | D18: S16 | E18: Cristal | F18: 15
A19: Tramo 4 | B19: 122–140 | C19: Perla 4 mm | D19: P04 | E19: Perla crema | F19: 20 | H19: Tono | J19: En el plano
A20: Tramo 3 | B20: 140–158 | C20: Rosa montada SS16 | D20: S16 | E20: Aguamarina | F20: 40 | H20: Capri | J20: =SUMIFS($F$5:$F$48,$E$5:$E$48,H20)
A21: Tramo 3 | B21: 140–158 | C21: Rosa montada SS16 | D21: S16 | E21: Champán | F21: 20 | H21: Aguamarina | J21: =SUMIFS($F$5:$F$48,$E$5:$E$48,H21)
A22: Tramo 3 | B22: 140–158 | C22: Rosa montada SS16 | D22: S16 | E22: Cristal | F22: 20 | H22: Cristal | J22: =SUMIFS($F$5:$F$48,$E$5:$E$48,H22)
A23: Tramo 3 | B23: 140–158 | C23: Rosa montada SS20 | D23: S20 | E23: Aguamarina | F23: 50 | H23: Champán | J23: =SUMIFS($F$5:$F$48,$E$5:$E$48,H23)
A24: Tramo 3 | B24: 140–158 | C24: Rosa montada SS20 | D24: S20 | E24: Cristal | F24: 30 | H24: Perla crema | J24: =SUMIFS($F$5:$F$48,$E$5:$E$48,H24)
A25: Tramo 3 | B25: 140–158 | C25: Perla 4 mm | D25: P04 | E25: Perla crema | F25: 30
A26: Tramo 2 | B26: 158–176 | C26: Rosa montada SS20 | D26: S20 | E26: Aguamarina | F26: 80
A27: Tramo 2 | B27: 158–176 | C27: Rosa montada SS20 | D27: S20 | E27: Capri | F27: 40 | H27: Zona | I27: Franja y (cm) | J27: Piedras | K27: Perlas
A28: Tramo 2 | B28: 158–176 | C28: Rosa montada SS20 | D28: S20 | E28: Cristal | F28: 60 | H28: Ancla | I28: =INDEX($B$5:$B$48,MATCH(H28,$A$5:$A$48,0)) | J28: =SUMIFS($F$5:$F$48,$A$5:$A$48,H28)-SUMIFS($F$5:$F$48,$A$5:$A$48,H28,$E$5:$E$48,"Perla crema") | K28: =SUMIFS($F$5:$F$48,$A$5:$A$48,H28,$E$5:$E$48,"Perla crema")
A29: Tramo 2 | B29: 158–176 | C29: Rosa montada SS30 | D29: S30 | E29: Aguamarina | F29: 40 | H29: Amarra | I29: =INDEX($B$5:$B$48,MATCH(H29,$A$5:$A$48,0)) | J29: =SUMIFS($F$5:$F$48,$A$5:$A$48,H29)-SUMIFS($F$5:$F$48,$A$5:$A$48,H29,$E$5:$E$48,"Perla crema") | K29: =SUMIFS($F$5:$F$48,$A$5:$A$48,H29,$E$5:$E$48,"Perla crema")
A30: Tramo 2 | B30: 158–176 | C30: Rosa montada SS30 | D30: S30 | E30: Capri | F30: 40 | H30: Ramitos de olivo | I30: =INDEX($B$5:$B$48,MATCH(H30,$A$5:$A$48,0)) | J30: =SUMIFS($F$5:$F$48,$A$5:$A$48,H30)-SUMIFS($F$5:$F$48,$A$5:$A$48,H30,$E$5:$E$48,"Perla crema") | K30: =SUMIFS($F$5:$F$48,$A$5:$A$48,H30,$E$5:$E$48,"Perla crema")
A31: Tramo 2 | B31: 158–176 | C31: Rosa montada SS30 | D31: S30 | E31: Cristal | F31: 20 | H31: Tramo 5 | I31: =INDEX($B$5:$B$48,MATCH(H31,$A$5:$A$48,0)) | J31: =SUMIFS($F$5:$F$48,$A$5:$A$48,H31)-SUMIFS($F$5:$F$48,$A$5:$A$48,H31,$E$5:$E$48,"Perla crema") | K31: =SUMIFS($F$5:$F$48,$A$5:$A$48,H31,$E$5:$E$48,"Perla crema")
A32: Tramo 2 | B32: 158–176 | C32: Chatón 8 mm | D32: C08 | E32: Aguamarina | F32: 6 | H32: Tramo 4 | I32: =INDEX($B$5:$B$48,MATCH(H32,$A$5:$A$48,0)) | J32: =SUMIFS($F$5:$F$48,$A$5:$A$48,H32)-SUMIFS($F$5:$F$48,$A$5:$A$48,H32,$E$5:$E$48,"Perla crema") | K32: =SUMIFS($F$5:$F$48,$A$5:$A$48,H32,$E$5:$E$48,"Perla crema")
A33: Tramo 2 | B33: 158–176 | C33: Chatón 8 mm | D33: C08 | E33: Cristal | F33: 6 | H33: Tramo 3 | I33: =INDEX($B$5:$B$48,MATCH(H33,$A$5:$A$48,0)) | J33: =SUMIFS($F$5:$F$48,$A$5:$A$48,H33)-SUMIFS($F$5:$F$48,$A$5:$A$48,H33,$E$5:$E$48,"Perla crema") | K33: =SUMIFS($F$5:$F$48,$A$5:$A$48,H33,$E$5:$E$48,"Perla crema")
A34: Tramo 2 | B34: 158–176 | C34: Perla 4 mm | D34: P04 | E34: Perla crema | F34: 70 | H34: Tramo 2 | I34: =INDEX($B$5:$B$48,MATCH(H34,$A$5:$A$48,0)) | J34: =SUMIFS($F$5:$F$48,$A$5:$A$48,H34)-SUMIFS($F$5:$F$48,$A$5:$A$48,H34,$E$5:$E$48,"Perla crema") | K34: =SUMIFS($F$5:$F$48,$A$5:$A$48,H34,$E$5:$E$48,"Perla crema")
A35: Tramo 2 | B35: 158–176 | C35: Perla 6 mm | D35: P06 | E35: Perla crema | F35: 40 | H35: Tramo 1 · pavé | I35: =INDEX($B$5:$B$48,MATCH(H35,$A$5:$A$48,0)) | J35: =SUMIFS($F$5:$F$48,$A$5:$A$48,H35)-SUMIFS($F$5:$F$48,$A$5:$A$48,H35,$E$5:$E$48,"Perla crema") | K35: =SUMIFS($F$5:$F$48,$A$5:$A$48,H35,$E$5:$E$48,"Perla crema")
A36: Tramo 1 · pavé | C36: Rosa montada SS30 | D36: S30 | E36: Aguamarina | F36: 70 | H36: Orla | I36: =INDEX($B$5:$B$48,MATCH(H36,$A$5:$A$48,0)) | J36: =SUMIFS($F$5:$F$48,$A$5:$A$48,H36)-SUMIFS($F$5:$F$48,$A$5:$A$48,H36,$E$5:$E$48,"Perla crema") | K36: =SUMIFS($F$5:$F$48,$A$5:$A$48,H36,$E$5:$E$48,"Perla crema")
A37: Tramo 1 · pavé | C37: Rosa montada SS30 | D37: S30 | E37: Capri | F37: 110 | H37: Total | J37: =SUM(J28:J36) | K37: =SUM(K28:K36)
A38: Tramo 1 · pavé | C38: Rosa montada SS30 | D38: S30 | E38: Cristal | F38: 60
A39: Tramo 1 · pavé | C39: Rosa montada SS40 | D39: S40 | E39: Aguamarina | F39: 60
A40: Tramo 1 · pavé | C40: Rosa montada SS40 | D40: S40 | E40: Capri | F40: 100
A41: Tramo 1 · pavé | C41: Chatón 10 mm | D41: C10 | E41: Aguamarina | F41: 18
...

Sheet Capas y peso
A1: Capas y presupuesto de peso
A2: Peso estimado 1,9–2,7 kg. El peso admisible de la réplica está PENDIENTE (prueba 6).
A4: N.º | B4: Cara | C4: Capa | D4: Qué es | E4: Materiales | F4: Fases | G4: Peso (g)
A5: 1 | B5: revés | C5: Sujeción | D5: Cinta de algodón de 25 mm cosida por el revés a lo largo del arranque, con tiras y velcro que cuelgan el manto desde detrás de la corona. Sin varillas ni piezas rígidas. | E5: M30, M31 | F5: F17 | G5: 40
A6: 2 | B6: revés | C6: Protector de roce | D6: Segundo forro de tafetán esmeralda hondo donde el manto apoya en la espalda del retablo, para que el metal no marque el terciopelo ni enganche hilos. | E6: M03 | F6: F17 | G6: 40
A7: 3 | B7: revés | C7: Forro | D7: Raso o tafetán esmeralda hondo. Va de vuelta a vuelta: en los bordes lo sustituyen las vueltas de terciopelo, para que desde el frente nunca se vea el forro. | E7: M02 | F7: F17 | G7: 240
A8: 4 | B8: revés | C8: Vueltas de los bordes | D8: Tiras de terciopelo de 6 cm vistos, con galón de oro de 1,5 cm, en el revés de los dos lados. Es lo que asoma por el frente, a los lados del retablo. | E8: M01, M29 | F8: F16 | G8: 95
A9: 5 | B9: revés | C9: Organza de soporte y refuerzo del pie | D9: Organza hilvanada por el revés del terciopelo bajo todo lo bordado; doble bajo el pavé. Cinta de algodón de 2 cm a lo largo del pie, bajo el pavé. | E9: M08, M09 | F9: F05 | G9: 130
A10: 6 | B10: exterior | C10: Cuerpo de terciopelo | D10: Terciopelo esmeralda profundo de un solo tono, con el pelo hacia arriba. Trapecio de 67,5 cm arriba, 150 cm al pie y 200 cm de alto. Si la tela no da el ancho del pie, dos nesgas que quedan bajo el galón. | E10: M01 | F10: F05 | G10: 790
A11: 7 | B11: exterior | C11: Bordado directo | D11: Todo lo que se borda sobre el manto extendido: el resplandor, los tallos, el horizonte, el Lago, las líneas de las olas y el ribete del arranque. Hilos metálicos sintéticos, por la humedad. | E11: M13, M17, M18, M19, M20, M21, M23 | F11: F07, F08, F12, F14 | G11: 130
A12: 8 | B12: exterior | C12: Apliques: cruz y paneles DTF | D12: Lo que se hace aparte y se aplica: la cruz en realce, bordada en bastidor sobre lienzo, y las 36 piezas DTF sobre raso marfil, rellenas con fieltro, cosidas por el borde y perfiladas con cordón. | E12: M04, M05, M06, M07, M10, M11, M13, M15, M16, M19, M22 | F12: F04, F06, F10, F12 | G12: 176
A13: 9 | B13: exterior | C13: Ancla y amarra | D13: El ancla de perlas y piedras champán dentro de un perfil de cordón de oro, que nace del pie de la cruz, y la amarra de once perlas que baja hacia el sol. La cose una sola persona. | E13: M13, M23, P04, P08, P06, S16, S20, C08, C10 | F13: F09, F11 | G13: 48
A14: 10 | B14: exterior | C14: Degradado de pedrería | D14: Sube desde la orla del pie y se aclara en cinco tramos: Capri y aguamarina abajo, cristal en medio, champán y perla arriba. Ninguna piedra toca la película DTF ni se acerca a menos de 4 cm de la amarra o del sol. | E14: S12, S16, S20, S30, S40, C08, C10, O13, P04, P06, P08, M23 | F14: F13 | G14: 378
A15: 11 | B15: exterior | C15: Orla | D15: Galón de volutas barrocas doradas de 7 cm y cordón de oro de 4 mm en los lados y el pie, atrapados en la costura del borde para que se vean por las dos caras. Perlas en las volutas solo por debajo de 0,45 H. | E15: M28, M14, P08, P06 | F15: F15 | G15: 221
F16: Total (g) | G16: =SUM(G5:G15)
F17: Total (kg) | G17: =G16/1000
F18: Peso admisible (kg)
F19: Margen (kg) | G19: =IF(G18="","pendiente",G18-G17)

Sheet Patrón
A1: Patrón: piezas de tela
A2: Medidas para H = 200 cm, W = 150 cm. Alturas × H/200; anchos × W/150.
A4: Pieza | B4: Nombre | C4: Material | D4: Cantidad | E4: Medidas | F4: Márgenes | G4: Nota
A5: P01 | B5: Cuerpo | C5: M01 | D5: 1 | E5: Trapecio: 67,5 cm arriba, 150 cm al pie, 200 cm de alto (lado de 204,2 cm) | F5: 1,5 cm en los lados, 3 cm arriba, 2 cm en el pie | G5: Pelo hacia arriba. Marcar el eje y las líneas de cota con hilván.
A6: P02 | B6: Nesgas del pie | C6: M01 | D6: 2 | E6: Con tela de 1,40 m: triángulo de 9 × 37 cm. Con 1,50 m: 4 × 13 cm | F6: Incluidos | G6: Solo si el ancho útil de la tela no llega a 153 cm. La costura queda a 6 cm o menos del borde, bajo el galón. Mismo sentido de pelo.
A7: P03 | B7: Vueltas | C7: M01 | D7: 2 | E7: Tira de 9 × 208 cm (6 vistos + 1,5 + 1,5) | F7: Incluidos | G7: Al hilo, de una sola pieza, pelo hacia arriba.
A8: P04 | B8: Forro | C8: M02 | D8: 1 | E8: Trapecio: 55,5 cm arriba, 138 cm al pie, 200 cm de alto | F8: 1,5 cm en los lados, 3 cm arriba, 2 cm en el pie | G8: El cuerpo menos las vueltas. Con tela de 1,50 m sale entero; con 1,40 m, dos mitades encontradas (cabeza con pie) en 2,1 m, unidas al centro.
A9: P05 | B9: Protector de roce | C9: M03 | D9: 1 | E9: ≈ 62 × 92 cm | F9: 1,5 cm | G9: PENDIENTE: copiar el contorno trasero del retablo y sumar 3 cm. Se corta al través.
A10: P06 | B10: Organza de soporte | C10: M08 | D10: 3 | E10: Corazón y azucenas 100 × 105 cm; agua 155 × 80 cm; doble del pie 155 × 32 cm | F10: 5 cm para el bastidor | G10: Se hilvana al revés del terciopelo antes de bordar.
A11: P07 | B11: Cinta de refuerzo del pie | C11: M09 | D11: 1 | E11: 2 × 155 cm | F11: — | G11: Por el revés, bajo el pavé.
A12: P08 | B12: Lienzo de la cruz | C12: M10 | D12: 1 | E12: 55 × 60 cm | F12: 8 cm por lado para el bastidor | G12: La cruz mide 39 × 43 cm.
A13: P09 | B13: Realce de la cruz | C13: M11 | D13: 3 | E13: Silueta de la cruz a −2, −5 y −8 mm | F13: — | G13: Tres capas escalonadas, como el fieltro: primero la pequeña (−8 mm), luego la de −5 mm y encima la grande (−2 mm), que cubre a las otras. Así el oro sube en cúpula.
A14: P10 | B14: Paneles DTF | C14: M04 | D14: 36 | E14: Ver la tabla de piezas DTF | F14: Corte a 6 mm del borde impreso | G14: Raso marfil con entretela termoadhesiva planchada antes de prensar. Más repuestos: ver el pliego.
A15: P11 | B15: Rellenos de fieltro (azucenas, capullos y crestas) | C15: M07 | D15: 2 capas por pieza (12 piezas, 24 recortes) | E15: Capa grande a −3 mm del borde impreso; capa pequeña a −8 mm | F15: — | G15: Primero la capa pequeña (−8 mm), centrada y cosida contra el terciopelo; encima la grande (−3 mm), que la cubre; después el raso. Así el relieve sube en cúpula, sin escalón visible. Las hojas y el olivo no llevan relleno.
A16: P12 | B16: Cinta de sujeción | C16: M30 | D16: 1 | E16: 70 cm en el arranque + tiras según los anclajes | F16: — | G16: PENDIENTE: puntos de anclaje en el retablo y las andas.

Sheet Piezas DTF
A1: Piezas DTF
A2: Pliego de 56 × 98 cm a 300 ppp. Raso cortado a 6 mm del borde impreso.
A4: Código | B4: Pieza | C4: Ancho (cm) | D4: Alto (cm) | E4: En el manto | F4: Repuestos | G4: Total impreso | H4: Fieltro | I4: ppp de origen | J4: Archivo | K4: Archivo espejo
A5: A1 | B5: Azucena de frente | C5: 12.1 | D5: 13 | E5: 2 | F5: 1 | G5: =E5+F5 | H5: sí | I5: 292 | J5: A1_azucena-de-frente.png | K5: A1e_azucena-de-frente.png
A6: A2 | B6: Azucena de perfil | C6: 12.03 | D6: 13 | E6: 2 | F6: 1 | G6: =E6+F6 | H6: sí | I6: 240 | J6: A2_azucena-de-perfil.png | K6: A2e_azucena-de-perfil.png
A7: B1 | B7: Capullo | C7: 3.2 | D7: 9 | E7: 2 | F7: 1 | G7: =E7+F7 | H7: sí | I7: 330 | J7: B1_capullo.png | K7: B1e_capullo.png
A8: H1 | B8: Hoja larga 1 | C8: 17.17 | D8: 2.53 | E8: 2 | F8: 1 | G8: =E8+F8 | H8: no | I8: 186 | J8: H1_hoja-larga-1.png | K8: H1e_hoja-larga-1.png
A9: H2 | B9: Hoja larga 2 | C9: 16.26 | D9: 2.85 | E9: 2 | F9: 0 | G9: =E9+F9 | H9: no | I9: 186 | J9: H2_hoja-larga-2.png | K9: H2e_hoja-larga-2.png
A10: H3 | B10: Hoja larga 3 | C10: 15.61 | D10: 2.63 | E10: 2 | F10: 1 | G10: =E10+F10 | H10: no | I10: 186 | J10: H3_hoja-larga-3.png | K10: H3e_hoja-larga-3.png
A11: H4 | B11: Hoja larga 4 | C11: 14.95 | D11: 3.11 | E11: 2 | F11: 0 | G11: =E11+F11 | H11: no | I11: 186 | J11: H4_hoja-larga-4.png | K11: H4e_hoja-larga-4.png
A12: O1 | B12: Hojita olivo 1 | C12: 3.01 | D12: 0.66 | E12: 2 | F12: 1 | G12: =E12+F12 | H12: no | I12: 666 | J12: O1_hojita-olivo-1.png | K12: O1e_hojita-olivo-1.png
A13: O2 | B13: Hojita olivo 2 | C13: 2.96 | D13: 0.81 | E13: 2 | F13: 1 | G13: =E13+F13 | H13: no | I13: 666 | J13: O2_hojita-olivo-2.png | K13: O2e_hojita-olivo-2.png
A14: O3 | B14: Hojita olivo 3 | C14: 3.18 | D14: 0.66 | E14: 2 | F14: 0 | G14: =E14+F14 | H14: no | I14: 666 | J14: O3_hojita-olivo-3.png | K14: O3e_hojita-olivo-3.png
A15: O4 | B15: Hojita olivo 4 | C15: 2.88 | D15: 0.73 | E15: 2 | F15: 0 | G15: =E15+F15 | H15: no | I15: 666 | J15: O4_hojita-olivo-4.png | K15: O4e_hojita-olivo-4.png
A16: O5 | B16: Hojita olivo 5 | C16: 2.97 | D16: 0.69 | E16: 2 | F16: 1 | G16: =E16+F16 | H16: no | I16: 666 | J16: O5_hojita-olivo-5.png | K16: O5e_hojita-olivo-5.png
... A22: C3 | B22: Cresta chica larga | C22: 18 | D22: 7.15 | E22: 2 | F22: 1 | G22: =E22+F22 | H22: sí | I22: 217 | J22: C3_cresta-chica-larga.png | K22: C3e_cresta-chica-larga.png
D23: Total | E23: =SUM(E5:E22) | F23: =SUM(F5:F22) | G23: =SUM(G5:G22)
D24: Recortes de fieltro | E24: =2*SUMIFS(E5:E22,H5:H22,"sí") | F24: dos capas por pieza rellena (−8 mm y −3 mm)

Sheet Herramientas
A1: Herramientas del taller
A2: Marcar si ya se tienen; lo que falte pasa a Compras.
A4: N.º | B4: Herramienta | C4: ¿Lo tenemos?
A5: 1 | B5: Bastidor de mesa largo (≥ 2,2 × 1,6 m) o caballetes con listones, para trabajar el manto extendido en tres franjas
A6: 2 | B6: Bastidor de rodillo de ≥ 50 × 55 cm para la cruz
A7: 3 | B7: Prensa térmica con control de temperatura, papel siliconado o teflón y almohadilla
A8: 4 | B8: Agujas de bordar n.º 9–10, agujas de pedrería n.º 10–12 y agujas curvas para el forro
A9: 5 | B9: Punzón o rueda de picar y polvo de estarcir, para pasar el dibujo de papel de seda al terciopelo
A10: 6 | B10: Tiza de sastre e hilo de hilvanar de color claro
A11: 7 | B11: Dinamómetro de pesca de 2 kg (prueba de tirón), balanza de cocina en gramos (muestras) y balanza colgante o de baño de 5 kg (peso final del manto)
A12: 8 | B12: Muselina (2,5 m) y cartulina dorada y marfil para la prueba de lectura a 10 m
